Workbook

Sheet COMPARADOR
A1: 📱 Comparativa de Celulares
B3: Selecciona los celulares a comparar
B5: Celular 1 | C5: Celular 2 | D5: Celular 3
B6: SAMSUNG GXY A17 128GB | C6: MOTOROLA G05 128GB | D6: SAMSUNG GXY A06 128GB
A8: Comparativa Detallada
A9: Especificación | B9: =B6 -> SAMSUNG GXY A17 128GB | C9: =C6 -> MOTOROLA G05 128GB | D9: =D6 -> SAMSUNG GXY A06 128GB
A10: Plan | B10: 69.9 | C10: 69.9 | D10: 29.9
A11: Contado | B11: {=IFERROR( INDEX(Caracteristicas!$A:$AAB, _xlfn.XMATCH($B$9,Caracteristicas!$A:$A,0), _xlfn.XMATCH($A11,Caracteristicas!$1:$1,0) ), "")} -> 639 | C11: {=IFERROR( INDEX(Caracteristicas!$A:$AAB, _xlfn.XMATCH($C$9,Caracteristicas!$A:$A,0), _xlfn.XMATCH($A11,Caracteristicas!$1:$1,0) ), "")} -> 349 | D11: {=IFERROR( INDEX(Caracteristicas!$A:$AAB, _xlfn.XMATCH($D$9,Caracteristicas!$A:$A,0), _xlfn.XMATCH($A11,Caracteristicas!$1:$1,0) ), "")} -> 349
A12: Cuota x 12 meses | B12: {=IFERROR( INDEX(Caracteristicas!$A:$AAB, _xlfn.XMATCH($B$9,Caracteristicas!$A:$A,0), _xlfn.XMATCH($A12,Caracteristicas!$1:$1,0) ), "")} -> 100 | C12: {=IFERROR( INDEX(Caracteristicas!$A:$AAB, _xlfn.XMATCH($C$9,Caracteristicas!$A:$A,0), _xlfn.XMATCH($A12,Caracteristicas!$1:$1,0) ), "")} -> 54 | D12: {=IFERROR( INDEX(Caracteristicas!$A:$AAB, _xlfn.XMATCH($D$9,Caracteristicas!$A:$A,0), _xlfn.XMATCH($A12,Caracteristicas!$1:$1,0) ), "")} -> 54
A13: Pantalla | B13: {=IFERROR( INDEX(Caracteristicas!$A:$AAB, _xlfn.XMATCH($B$9,Caracteristicas!$A:$A,0), _xlfn.XMATCH($A13,Caracteristicas!$1:$1,0) ), "")} -> 6.7", FHD+, Super AMOLED | C13: {=IFERROR( INDEX(Caracteristicas!$A:$AAB, _xlfn.XMATCH($C$9,Caracteristicas!$A:$A,0), _xlfn.XMATCH($A13,Caracteristicas!$1:$1,0) ), "")} -> 6.72", HD+, LCD | D13: {=IFERROR( INDEX(Caracteristicas!$A:$AAB, _xlfn.XMATCH($D$9,Caracteristicas!$A:$A,0), _xlfn.XMATCH($A13,Caracteristicas!$1:$1,0) ), "")} -> 6.7", HD+, PLS
A14: Peso | B14: {=IFERROR( INDEX(Caracteristicas!$A:$AAB, _xlfn.XMATCH($B$9,Caracteristicas!$A:$A,0), _xlfn.XMATCH($A14,Caracteristicas!$1:$1,0) ), "")} -> 190 g | C14: {=IFERROR( INDEX(Caracteristicas!$A:$AAB, _xlfn.XMATCH($C$9,Caracteristicas!$A:$A,0), _xlfn.XMATCH($A14,Caracteristicas!$1:$1,0) ), "")} -> 189 g | D14: {=IFERROR( INDEX(Caracteristicas!$A:$AAB, _xlfn.XMATCH($D$9,Caracteristicas!$A:$A,0), _xlfn.XMATCH($A14,Caracteristicas!$1:$1,0) ), "")} -> 189 g
A15: Resistencia | B15: {=IFERROR( INDEX(Caracteristicas!$A:$AAB, _xlfn.XMATCH($B$9,Caracteristicas!$A:$A,0), _xlfn.XMATCH($A15,Caracteristicas!$1:$1,0) ), "")} -> IP54 | C15: {=IFERROR( INDEX(Caracteristicas!$A:$AAB, _xlfn.XMATCH($C$9,Caracteristicas!$A:$A,0), _xlfn.XMATCH($A15,Caracteristicas!$1:$1,0) ), "")} -> IP54 | D15: {=IFERROR( INDEX(Caracteristicas!$A:$AAB, _xlfn.XMATCH($D$9,Caracteristicas!$A:$A,0), _xlfn.XMATCH($A15,Caracteristicas!$1:$1,0) ), "")} -> -
A16: Tasa de Refresco | B16: {=IFERROR( INDEX(Caracteristicas!$A:$AAB, _xlfn.XMATCH($B$9,Caracteristicas!$A:$A,0), _xlfn.XMATCH($A16,Caracteristicas!$1:$1,0) ), "")} -> 90 Hz | C16: {=IFERROR( INDEX(Caracteristicas!$A:$AAB, _xlfn.XMATCH($C$9,Caracteristicas!$A:$A,0), _xlfn.XMATCH($A16,Caracteristicas!$1:$1,0) ), "")} -> 90 Hz | D16: {=IFERROR( INDEX(Caracteristicas!$A:$AAB, _xlfn.XMATCH($D$9,Caracteristicas!$A:$A,0), _xlfn.XMATCH($A16,Caracteristicas!$1:$1,0) ), "")} -> 60 Hz
A17: Procesador | B17: {=IFERROR( INDEX(Caracteristicas!$A:$AAB, _xlfn.XMATCH($B$9,Caracteristicas!$A:$A,0), _xlfn.XMATCH($A17,Caracteristicas!$1:$1,0) ), "")} -> Exynos 1330 (5 nm) | C17: {=IFERROR( INDEX(Caracteristicas!$A:$AAB, _xlfn.XMATCH($C$9,Caracteristicas!$A:$A,0), _xlfn.XMATCH($A17,Caracteristicas!$1:$1,0) ), "")} -> G81 Extreme (12 nm) | D17: {=IFERROR( INDEX(Caracteristicas!$A:$AAB, _xlfn.XMATCH($D$9,Caracteristicas!$A:$A,0), _xlfn.XMATCH($A17,Caracteristicas!$1:$1,0) ), "")} -> Helio G85 (12 nm)
A18: Antutu | B18: {=IFERROR( INDEX(Caracteristicas!$A:$AAB, _xlfn.XMATCH($B$9,Caracteristicas!$A:$A,0), _xlfn.XMATCH($A18,Caracteristicas!$1:$1,0) ), "")} -> 419K | C18: {=IFERROR( INDEX(Caracteristicas!$A:$AAB, _xlfn.XMATCH($C$9,Caracteristicas!$A:$A,0), _xlfn.XMATCH($A18,Caracteristicas!$1:$1,0) ), "")} -> 262K | D18: {=IFERROR( INDEX(Caracteristicas!$A:$AAB, _xlfn.XMATCH($D$9,Caracteristicas!$A:$A,0), _xlfn.XMATCH($A18,Caracteristicas!$1:$1,0) ), "")} -> 225K
A19: RAM | B19: {=IFERROR( INDEX(Caracteristicas!$A:$AAB, _xlfn.XMATCH($B$9,Caracteristicas!$A:$A,0), _xlfn.XMATCH($A19,Caracteristicas!$1:$1,0) ), "")} -> 8 GB (física) + hasta 8 GB (RAM Plus) | C19: {=IFERROR( INDEX(Caracteristicas!$A:$AAB, _xlfn.XMATCH($C$9,Caracteristicas!$A:$A,0), _xlfn.XMATCH($A19,Caracteristicas!$1:$1,0) ), "")} -> 4 GB (física) + hasta 8 GB (RAM Boost) | D19: {=IFERROR( INDEX(Caracteristicas!$A:$AAB, _xlfn.XMATCH($D$9,Caracteristicas!$A:$A,0), _xlfn.XMATCH($A19,Caracteristicas!$1:$1,0) ), "")} -> 4 GB (física) + hasta 4 GB (RAM Plus)
A20: Almacenamiento | B20: {=IFERROR( INDEX(Caracteristicas!$A:$AAB, _xlfn.XMATCH($B$9,Caracteristicas!$A:$A,0), _xlfn.XMATCH($A20,Caracteristicas!$1:$1,0) ), "")} -> 128 GB | C20: {=IFERROR( INDEX(Caracteristicas!$A:$AAB, _xlfn.XMATCH($C$9,Caracteristicas!$A:$A,0), _xlfn.XMATCH($A20,Caracteristicas!$1:$1,0) ), "")} -> 128 GB eMMC 5.1 | D20: {=IFERROR( INDEX(Caracteristicas!$A:$AAB, _xlfn.XMATCH($D$9,Caracteristicas!$A:$A,0), _xlfn.XMATCH($A20,Caracteristicas!$1:$1,0) ), "")} -> 128 GB eMMC 5.1
A21: Cámaras | B21: {=IFERROR( INDEX(Caracteristicas!$A:$AAB, _xlfn.XMATCH($B$9,Caracteristicas!$A:$A,0), _xlfn.XMATCH($A21,Caracteristicas!$1:$1,0) ), "")} -> 50 Mpx (ƒ/ 1.8) + 5 Mpx UGA (ƒ/ 2.2) + 2 Mpx MACRO (ƒ/ 2.4) | C21: {=IFERROR( INDEX(Caracteristicas!$A:$AAB, _xlfn.XMATCH($C$9,Caracteristicas!$A:$A,0), _xlfn.XMATCH($A21,Caracteristicas!$1:$1,0) ), "")} -> 50 Mpx (ƒ/ 1.8) + Flicker Sensor | D21: {=IFERROR( INDEX(Caracteristicas!$A:$AAB, _xlfn.XMATCH($D$9,Caracteristicas!$A:$A,0), _xlfn.XMATCH($A21,Caracteristicas!$1:$1,0) ), "")} -> 50 Mpx (ƒ/ 1.8) + 2 Mpx (ƒ/ 2.4)
A22: Estabilización Óptica | B22: {=IFERROR( INDEX(Caracteristicas!$A:$AAB, _xlfn.XMATCH($B$9,Caracteristicas!$A:$A,0), _xlfn.XMATCH($A22,Caracteristicas!$1:$1,0) ), "")} -> SI | C22: {=IFERROR( INDEX(Caracteristicas!$A:$AAB, _xlfn.XMATCH($C$9,Caracteristicas!$A:$A,0), _xlfn.XMATCH($A22,Caracteristicas!$1:$1,0) ), "")} -> NO | D22: {=IFERROR( INDEX(Caracteristicas!$A:$AAB, _xlfn.XMATCH($D$9,Caracteristicas!$A:$A,0), _xlfn.XMATCH($A22,Caracteristicas!$1:$1,0) ), "")} -> NO
... A29: Huella | B29: {=IFERROR( INDEX(Caracteristicas!$A:$AAB, _xlfn.XMATCH($B$9,Caracteristicas!$A:$A,0), _xlfn.XMATCH($A29,Caracteristicas!$1:$1,0) ), "")} -> lateral | C29: {=IFERROR( INDEX(Caracteristicas!$A:$AAB, _xlfn.XMATCH($C$9,Caracteristicas!$A:$A,0), _xlfn.XMATCH($A29,Caracteristicas!$1:$1,0) ), "")} -> lateral | D29: {=IFERROR( INDEX(Caracteristicas!$A:$AAB, _xlfn.XMATCH($D$9,Caracteristicas!$A:$A,0), _xlfn.XMATCH($A29,Caracteristicas!$1:$1,0) ), "")} -> lateral

Sheet Caracteristicas
A1: EQUIPO | B1: CONTADO | C1: Cuota x 12 meses | D1: Pantalla | E1: Peso | F1: Resistencia | G1: Tasa de Refresco | H1: Procesador | I1: Antutu | J1: RAM | K1: Almacenamiento | L1: Ampliable | M1: Cámaras | N1: Estabilización Óptica | O1: Grabación de Video | P1: Cámara Frontal | Q1: Batería | R1: Carga Rápida | S1: Carga Inalámbrica | T1: Bluetooth | U1: NFC | V1: Huella | W1: Actualización | AF1: PLANES
A2: HONOR X5B 128GB | B2: =IFERROR( _xlfn.XLOOKUP("*"&SUBSTITUTE(TRIM(A2)," ","*")&"*", CAM!$A:$A, CAM!$K:$K, "", 2), "") -> 299 | C2: =IFERROR( _xlfn.XLOOKUP("*"&SUBSTITUTE(TRIM(A2)," ","*")&"*", CAM!$A:$A, CAM!$Z:$Z, "", 2), "")/12 -> 46 | D2: 6.56", HD+, TFT LCD (IPS) | E2: 194 g | F2: - | G2: 90 Hz | H2: Helio G36 (12 nm) | I2: 127K | J2: 4 GB (física) + hasta 4 GB (RAM Boost) | K2: 128 GB | L2: Hasta 1Tb | M2: 13 Mpx (ƒ/ 1.8) + 0.3 Mpx | N2: NO | O2: 1080p@30fps | P2: 5 Mpx | Q2: 5200 mAh | R2: 10.0W | S2: NO | T2: 5.1 | U2: NO | V2: lateral | W2: ~2 años | AF2: 29.9
A3: HONOR X5C 128GB | B3: =IFERROR( _xlfn.XLOOKUP("*"&SUBSTITUTE(TRIM(A3)," ","*")&"*", CAM!$A:$A, CAM!$K:$K, "", 2), "") -> 399 | C3: =IFERROR( _xlfn.XLOOKUP("*"&SUBSTITUTE(TRIM(A3)," ","*")&"*", CAM!$A:$A, CAM!$Z:$Z, "", 2), "")/12 -> 58 | D3: 6.74", HD+, TFT LCD (IPS) | E3: 186 g | F3: - | G3: 90 Hz | H3: Helio G81 (12 nm) | I3: 280K | J3: 4 GB (física) + hasta 4 GB (RAM Boost) | K3: 128 GB | L3: Hasta 1Tb | M3: 50 Mpx (ƒ/ 2.2) + 0.8 Mpx (QVGA) | N3: NO | O3: 1080p@30fps | P3: 5 Mpx | Q3: 5260 mAh | R3: 15.0W | S3: NO | T3: 5.1 | U3: NO | V3: lateral | W3: -
A4: HONOR X6C 256GB | B4: =IFERROR( _xlfn.XLOOKUP("*"&SUBSTITUTE(TRIM(A4)," ","*")&"*", CAM!$A:$A, CAM!$K:$K, "", 2), "") -> 559 | C4: =IFERROR( _xlfn.XLOOKUP("*"&SUBSTITUTE(TRIM(A4)," ","*")&"*", CAM!$A:$A, CAM!$Z:$Z, "", 2), "")/12 -> 82 | D4: 6.56", HD+, TFT LCD (IPS) | E4: 199 g | F4: IP64 | G4: 120Hz | H4: Helio G81 Ultra (12 nm) | I4: 287K | J4: 6 GB (física) + hasta 6 GB (RAM Boost) | K4: 256 GB | L4: Hasta 1Tb | M4: 50 Mpx (ƒ/ 1.8) + 2 Mpx Retrato (ƒ/ 2.4) | N4: NO | O4: 1080p@30fps | P4: 5 Mpx | Q4: 5300 mAh | R4: 35.0W | S4: NO | T4: 5.1 | U4: NO | V4: lateral | W4: ~2 años | AF4: 39.9
A5: HONOR X7C 256GB | B5: =IFERROR( _xlfn.XLOOKUP("*"&SUBSTITUTE(TRIM(A5)," ","*")&"*", CAM!$A:$A, CAM!$K:$K, "", 2), "") -> 679 | C5: =IFERROR( _xlfn.XLOOKUP("*"&SUBSTITUTE(TRIM(A5)," ","*")&"*", CAM!$A:$A, CAM!$Z:$Z, "", 2), "")/12 -> 96 | D5: 6.77", HD, LCD IPS | E5: 196 g | F5: IP64 | G5: 120Hz | H5: Snapdragon 685 (6 nm) | I5: 321K | J5: 8 GB (física) + hasta 8 GB (RAM Boost) | K5: 256 GB | L5: - | M5: 108 Mpx (ƒ/ 1.8) + 2 Mpx Retrato (ƒ/ 2.4) | N5: NO | O5: 1080p@30fps | P5: 8 Mpx | Q5: 6000 mAh | R5: 35.0W | S5: NO | T5: 5.1 | U5: NO | V5: lateral | W5: ~2 años | AF5: 49.9
A6: HONOR X7D 256GB LTE | B6: =IFERROR( _xlfn.XLOOKUP("*"&SUBSTITUTE(TRIM(A6)," ","*")&"*", CAM!$A:$A, CAM!$K:$K, "", 2), "") -> 789 | C6: =IFERROR( _xlfn.XLOOKUP("*"&SUBSTITUTE(TRIM(A6)," ","*")&"*", CAM!$A:$A, CAM!$Z:$Z, "", 2), "")/12 -> 118 | D6: 6.77", HD, TFT LCD | E6: 208 g | F6: IP65 | G6: 120Hz | H6: Snapdragon 685 (6 nm) | I6: 350K | J6: 8 GB (física) + hasta 8 GB (RAM Boost) | K6: 256 GB | L6: - | M6: 108 Mpx (ƒ/ 1.8) + 2 Mpx (ƒ/ 2.4) | N6: NO | O6: 1080p@30fps | P6: 8 Mpx | Q6: 6500mAh | R6: 35.0W | S6: NO | T6: 5 | U6: - | V6: lateral | W6: -
A7: HONOR X8C 256GB | B7: =IFERROR( _xlfn.XLOOKUP("*"&SUBSTITUTE(TRIM(A7)," ","*")&"*", CAM!$A:$A, CAM!$K:$K, "", 2), "") -> 819 | C7: =IFERROR( _xlfn.XLOOKUP("*"&SUBSTITUTE(TRIM(A7)," ","*")&"*", CAM!$A:$A, CAM!$Z:$Z, "", 2), "")/12 -> 119 | D7: 6.77", FHD+, AMOLED | E7: 174 g | F7: IP64 | G7: 120Hz | H7: Snapdragon 685 (6 nm) | I7: 321K | J7: 8 GB (física) + hasta 8 GB (RAM Boost) | K7: 256 GB | L7: - | M7: 108 Mpx (ƒ/ 1.75) + 5 Mpx Retrato (ƒ/ 2.2) | N7: SI | O7: 1080p@30fps | P7: 50 MP | Q7: 5000 mAh | R7: 35.0W | S7: NO | T7: 5 | U7: NO | V7: Pantalla | W7: ~2 años | AF7: 59.9
A8: HONOR MAGIC 7 LITE 512GB | B8: =IFERROR( _xlfn.XLOOKUP("*"&SUBSTITUTE(TRIM(A8)," ","*")&"*", CAM!$A:$A, CAM!$K:$K, "", 2), "") -> 1119 | C8: =IFERROR( _xlfn.XLOOKUP("*"&SUBSTITUTE(TRIM(A8)," ","*")&"*", CAM!$A:$A, CAM!$Z:$Z, "", 2), "")/12 -> 159 | D8: 6.78", QHD, AMOLED | E8: 189 g | F8: IP65 | G8: 120 Hz | H8: Snapdragon 6 Gen1 (4 nm) | I8: 575K | J8: 8 GB (física) + hasta 8 GB (RAM Boost) | K8: 512 GB | L8: - | M8: 108 Mpx (ƒ/ 1.75) + 5 Mpx UGA (ƒ/ 2.2) | N8: SI | O8: 4K | P8: 16 Mpx | Q8: 6600 mAh | R8: 66.0W | S8: NO | T8: 5.1 | U8: - | V8: Pantalla | W8: 47849 | AF8: 69.9
A9: HONOR MAGIC 8 LITE 512GB 5G | B9: =IFERROR( _xlfn.XLOOKUP("*"&SUBSTITUTE(TRIM(A9)," ","*")&"*", CAM!$A:$A, CAM!$K:$K, "", 2), "") -> 1649 | C9: =IFERROR( _xlfn.XLOOKUP("*"&SUBSTITUTE(TRIM(A9)," ","*")&"*", CAM!$A:$A, CAM!$Z:$Z, "", 2), "")/12 -> 240 | D9: 6.79", QHD, AMOLED | E9: 193 g | F9: IP68, IP69 y IP69K | G9: 120 Hz | H9: Snapdragon 6 Gen 4 (4 nm) | I9: 894K | J9: 8 GB (física) + hasta 8 GB (RAM Boost) | K9: 512 GB | L9: - | M9: 108 Mpx (ƒ/ 1.75) + 5 Mpx UGA (ƒ/ 2.2) | N9: SI | O9: 4K | P9: 16 Mpx | Q9: 8300mAh | R9: 66.0W | S9: NO | T9: 5.2 | U9: NO | V9: Pantalla | W9: -
A10: HONOR 400 LITE | B10: =IFERROR( _xlfn.XLOOKUP("*"&SUBSTITUTE(TRIM(A10)," ","*")&"*", CAM!$A:$A, CAM!$K:$K, "", 2), "") -> 1109 | C10: =IFERROR( _xlfn.XLOOKUP("*"&SUBSTITUTE(TRIM(A10)," ","*")&"*", CAM!$A:$A, CAM!$Z:$Z, "", 2), "")/12 -> 157 | D10: 6.7", FHD, AMOLED | E10: 171 g | F10: IP65 | G10: 120 Hz | H10: Dimensity 7025 (6 nm) | I10: 470k | J10: 8 GB (física) + hasta 8 GB (RAM Boost) | K10: 256 GB | L10: - | M10: 108 Mpx (ƒ/ 1.75) + 5 Mpx UGA (ƒ/ 2.2) | N10: NO | O10: 1080p@30fps | P10: 16 Mpx | Q10: 5230 mAh | R10: 33W | S10: NO | T10: 5.3 | U10: NO | V10: Pantalla | W10: -
A11: HONOR 400 | B11: =IFERROR( _xlfn.XLOOKUP("*"&SUBSTITUTE(TRIM(A11)," ","*")&"*", CAM!$A:$A, CAM!$K:$K, "", 2), "") -> 1699 | C11: =IFERROR( _xlfn.XLOOKUP("*"&SUBSTITUTE(TRIM(A11)," ","*")&"*", CAM!$A:$A, CAM!$Z:$Z, "", 2), "")/12 -> 241 | D11: 6.55", QHD, AMOLED | E11: 184 g | F11: IP66 | G11: 120 Hz | H11: Snapdragon 7 Gen 3 (4 nm) | I11: 845K | J11: 12 GB (física) + hasta 12 GB (RAM Boost) | K11: 512 GB UFS 3.1 | L11: - | M11: 200 Mpx (ƒ/ 1.9) + 12 Mpx UGA + Macro (ƒ/ 2.2) | N11: SI | O11: 4K | P11: 50 Mpx | Q11: 5300 mAh | R11: 66.0W | S11: NO | T11: 5.4 | U11: SI | V11: Pantalla | W11: 47969 | AF11: 79.9
A12: IPHONE 13 128GB | B12: =IFERROR( _xlfn.XLOOKUP("*"&SUBSTITUTE(TRIM(A12)," ","*")&"*", CAM!$A:$A, CAM!$K:$K, "", 2), "") -> 1989 | C12: =IFERROR( _xlfn.XLOOKUP("*"&SUBSTITUTE(TRIM(A12)," ","*")&"*", CAM!$A:$A, CAM!$Z:$Z, "", 2), "")/12 -> 253 | D12: 6.1", FHD, Oled | E12: 174 g | F12: IP68 | G12: 60 Hz | H12: A15 Bionic (5 nm) | I12: 1256K | J12: 4 GB | K12: 128 GB | L12: NO | M12: 12 Mpx (ƒ/ 1.6) + 12 Mpx UGA (ƒ/ 2.4) | N12: SI | O12: 4K | P12: 12 Mpx | Q12: 3240 mAh | R12: 20.0W | S12: SI | T12: 5 | U12: SI | V12: NO | W12: 46753 | AF12: 99.9
A13: IPHONE 15 128GB | B13: =IFERROR( _xlfn.XLOOKUP("*"&SUBSTITUTE(TRIM(A13)," ","*")&"*", CAM!$A:$A, CAM!$K:$K, "", 2), "") -> 2509 | C13: =IFERROR( _xlfn.XLOOKUP("*"&SUBSTITUTE(TRIM(A13)," ","*")&"*", CAM!$A:$A, CAM!$Z:$Z, "", 2), "")/12 -> 355 | D13: 6.1", QHD, Oled | E13: 171 g | F13: IP68 | G13: 60 Hz | H13: A16 Bionic (4 nm) | I13: 1470k | J13: 6 GB | K13: 128 GB NVMe | L13: NO | M13: 48 Mpx (ƒ/ 1.6) + 12 Mpx UGA (ƒ/ 2.4) | N13: SI | O13: 4K | P13: 12 Mpx | Q13: 3349 mAh | R13: 18.0W | S13: SI | T13: 5.3 | U13: SI | V13: NO | W13: -
A14: IPHONE 16 128GB | B14: =IFERROR( _xlfn.XLOOKUP("*"&SUBSTITUTE(TRIM(A14)," ","*")&"*", CAM!$A:$A, CAM!$K:$K, "", 2), "") -> 2939 | C14: =IFERROR( _xlfn.XLOOKUP("*"&SUBSTITUTE(TRIM(A14)," ","*")&"*", CAM!$A:$A, CAM!$Z:$Z, "", 2), "")/12 -> 416 | D14: 6.1", QHD, Oled | E14: 171 g | F14: IP68 | G14: 60 Hz | H14: A18 Bionic (3 nm) | I14: 1586k | J14: 8 GB | K14: 128 GB NVMe | L14: NO | M14: 48 Mpx (ƒ/ 1.6) + 12 Mpx UGA (ƒ/ 2.2) | N14: SI | O14: 4K | P14: 12 Mpx | Q14: 3561 mAh | R14: 18.0W | S14: SI | T14: 5.3 | U14: SI | V14: NO | W14: -
A15: IPHONE 17 256GB | B15: =IFERROR( _xlfn.XLOOKUP("*"&SUBSTITUTE(TRIM(A15)," ","*")&"*", CAM!$A:$A, CAM!$K:$K, "", 2), "") -> 3579 | C15: =IFERROR( _xlfn.XLOOKUP("*"&SUBSTITUTE(TRIM(A15)," ","*")&"*", CAM!$A:$A, CAM!$Z:$Z, "", 2), "")/12 -> 507 | D15: 6.3", QHD, Oled | E15: 177 g | F15: IP68 | G15: 120 Hz | H15: A19 Bionic (3 nm) | I15: 2084k | J15: 8 GB | K15: 256 GB NVMe | L15: NO | M15: 48 Mpx (ƒ/ 1.6) + 12 Mpx UGA (ƒ/ 2.2) | N15: SI | O15: 4k | P15: 18 Mpx | Q15: 3600 mAh | R15: 18.0W | S15: SI | T15: 6 | U15: SI | V15: NO | W15: -
A16: IPHONE 17 PRO MAX 512GB | B16: =IFERROR( _xlfn.XLOOKUP("*"&SUBSTITUTE(TRIM(A16)," ","*")&"*", CAM!$A:$A, CAM!$K:$K, "", 2), "") -> 6139 | C16: =IFERROR( _xlfn.XLOOKUP("*"&SUBSTITUTE(TRIM(A16)," ","*")&"*", CAM!$A:$A, CAM!$Z:$Z, "", 2), "")/12 -> 870 | D16: 6.9", QHD, Oled | E16: 233 g | F16: IP68 | G16: 120 Hz | H16: A19 Pro (3 nm) | I16: 2309k | J16: 12 GB | K16: 512 GB NVMe | L16: NO | M16: 48 Mpx (ƒ/ 1.6) + 48 Mpx UGA (ƒ/ 2.2) + 48 Mpx Teleobjetivo (ƒ/ 2.8) | N16: SI | O16: 4k | P16: 18 Mpx | Q16: 4823 mAh | R16: 40W | S16: SI, 25W | T16: 6 | U16: SI | V16: FACEID | W16: 7 años desde 2026
A17: MOTOROLA G05 128GB | B17: =IFERROR( _xlfn.XLOOKUP("*"&SUBSTITUTE(TRIM(A17)," ","*")&"*", CAM!$A:$A, CAM!$K:$K, "", 2), "") -> 349 | C17: =IFERROR( _xlfn.XLOOKUP("*"&SUBSTITUTE(TRIM(A17)," ","*")&"*", CAM!$A:$A, CAM!$Z:$Z, "", 2), "")/12 -> 54 | D17: 6.72", HD+, LCD | E17: 189 g | F17: IP54 | G17: 90 Hz | H17: G81 Extreme (12 nm) | I17: 262K | J17: 4 GB (física) + hasta 8 GB (RAM Boost) | K17: 128 GB eMMC 5.1 | L17: Hasta 1Tb | M17: 50 Mpx (ƒ/ 1.8) + Flicker Sensor | N17: NO | O17: 1080p@30fps | P17: 8 Mpx | Q17: 5200 mAh | R17: 18.0W | S17: NO | T17: 5.4 | U17: NO | V17: lateral | W17: 46784 | AF17: PLANES MT
A18: MOTOROLA G06 128GB LTE | B18: =IFERROR( _xlfn.XLOOKUP("*"&SUBSTITUTE(TRIM(A18)," ","*")&"*", CAM!$A:$A, CAM!$K:$K, "", 2), "") -> 319 | C18: =IFERROR( _xlfn.XLOOKUP("*"&SUBSTITUTE(TRIM(A18)," ","*")&"*", CAM!$A:$A, CAM!$Z:$Z, "", 2), "")/12 -> 47 | D18: 6.72", HD+, LCD | E18: 194 g | F18: IP64 | G18: 120 Hz | H18: G81 Extreme (12 nm) | I18: 262K | J18: 4 GB (física) + hasta 8 GB (RAM Boost) | K18: 128 GB eMMC 5.1 | L18: Hasta 1Tb | M18: 50 Mpx (ƒ/ 1.8) + 0.3 Mpx | N18: NO | O18: 1080p@30fps | P18: 8 Mpx | Q18: 5200 mAh | R18: 18.0W | S18: NO | T18: 5.4 | U18: NO | V18: lateral | W18: 7 años
A19: MOTOROLA G15 256GB | B19: =IFERROR( _xlfn.XLOOKUP("*"&SUBSTITUTE(TRIM(A19)," ","*")&"*", CAM!$A:$A, CAM!$K:$K, "", 2), "") -> 379 | C19: =IFERROR( _xlfn.XLOOKUP("*"&SUBSTITUTE(TRIM(A19)," ","*")&"*", CAM!$A:$A, CAM!$Z:$Z, "", 2), "")/12 -> 54 | D19: 6.72", FHD+, LCD | E19: 190 g | F19: IP54 | G19: 60 Hz | H19: G81 Extreme (12 nm) | I19: 288K | J19: 4 GB (física) + hasta 8 GB (RAM Boost) | K19: 256 GB eMMC 5.1 | L19: - | M19: 50 Mpx (ƒ/ 1.8) + 5 Mpx UGA (ƒ/ 2.4) | N19: NO | O19: 1080p@30fps | P19: 8 Mpx | Q19: 5200 mAh | R19: 20.0W | S19: NO | T19: 5.4 | U19: SI | V19: lateral | W19: 3 años
A20: MOTOROLA G17 256GB LTE | B20: =IFERROR( _xlfn.XLOOKUP("*"&SUBSTITUTE(TRIM(A20)," ","*")&"*", CAM!$A:$A, CAM!$K:$K, "", 2), "") -> 599 | C20: =IFERROR( _xlfn.XLOOKUP("*"&SUBSTITUTE(TRIM(A20)," ","*")&"*", CAM!$A:$A, CAM!$Z:$Z, "", 2), "")/12 -> 85 | D20: 6.72", FHD+, LCD | E20: 190 g | F20: IP64 | G20: 90 Hz | H20: G81 Extreme (12 nm) | I20: 288K | J20: 4 GB (física) + hasta 8 GB (RAM Boost) | K20: 256 GB eMMC 5.1 | L20: - | M20: 50 Mpx (ƒ/ 1.88) + 5 Mpx UGA (ƒ/ 2.2) | N20: NO | O20: 1080p@30fps | P20: 32 Mpx | Q20: 5200 mAh | R20: 18.0W | S20: NO | T20: 5.4 | U20: NO | V20: lateral | W20: -
A21: MOTOROLA G56 256GB | B21: =IFERROR( _xlfn.XLOOKUP("*"&SUBSTITUTE(TRIM(A21)," ","*")&"*", CAM!$A:$A, CAM!$K:$K, "", 2), "") -> 739 | C21: =IFERROR( _xlfn.XLOOKUP("*"&SUBSTITUTE(TRIM(A21)," ","*")&"*", CAM!$A:$A, CAM!$Z:$Z, "", 2), "")/12 -> 121 | D21: 6.72", FHD+, LCD | E21: 200 g | F21: IP68, IP69K, MIL-STD-810H | G21: 120 Hz | H21: Dimensity 7060 (6 nm) | I21: 475K | J21: 8 GB (física) | K21: 256 GB UFS 2.1 | L21: Hasta 2Tb | M21: 50 Mpx (ƒ/ 1.88) + 8 Mpx UGA (ƒ/ 2.2) | N21: SI | O21: 1080p@30fps | P21: 32 Mpx | Q21: 5200 mAh | R21: 33.0W | S21: NO | T21: 5.3 | U21: SI | V21: lateral | W21: 4 años
A22: MOTOROLA G77 256GB 5G | B22: =IFERROR( _xlfn.XLOOKUP("*"&SUBSTITUTE(TRIM(A22)," ","*")&"*", CAM!$A:$A, CAM!$K:$K, "", 2), "") -> 919 | C22: =IFERROR( _xlfn.XLOOKUP("*"&SUBSTITUTE(TRIM(A22)," ","*")&"*", CAM!$A:$A, CAM!$Z:$Z, "", 2), "")/12 -> 134 | D22: 6.78", FHD+, AMOLED | E22: 182 g | F22: IP64 , MIL-STD-810H | G22: 120 Hz | H22: Dimensity 6400 (4 nm) | I22: 449K | J22: 8 GB (física) | K22: 256 GB UFS 2.1 | L22: Hasta 2Tb | M22: 108 Mpx (ƒ/ 1.7) + 8 Mpx UGA (ƒ/ 2.2) | N22: SI | O22: 1080p@30fps | P22: 32 Mpx | Q22: 5200 mAh | R22: 33.0W | S22: NO | T22: 5.4 | U22: SI | V22: Pantalla | W22: 4 años
A23: MOTOROLA EDGE 60 FUSION 256GB 5G | B23: =IFERROR( _xlfn.XLOOKUP("*"&SUBSTITUTE(TRIM(A23)," ","*")&"*", CAM!$A:$A, CAM!$K:$K, "", 2), "") -> 1039 | C23: =IFERROR( _xlfn.XLOOKUP("*"&SUBSTITUTE(TRIM(A23)," ","*")&"*", CAM!$A:$A, CAM!$Z:$Z, "", 2), "")/12 -> 147 | D23: 6.67", QHD+, pOLED | E23: 178 g | F23: IP68, IP69K, MIL-STD-810H | G23: 120 Hz | H23: Dimensity 7300 (4 nm) | I23: 640K | J23: 8 GB (física) + hasta 8 GB (RAM Boost) | K23: 256 GB UFS 2.1 | L23: - | M23: 50 Mpx (ƒ/ 1.88) + 13 Mpx UGA (ƒ/ 2.2) + 5 Mpx Retrato | N23: SI | O23: 4K | P23: 32 Mpx | Q23: 5200 mAh | R23: 68.0W | S23: NO | T23: 5.4 | U23: SI | V23: Pantalla | W23: 4 años
A24: MOTOROLA EDGE 70 FUSION 256GB 5G | B24: =IFERROR( _xlfn.XLOOKUP("*"&SUBSTITUTE(TRIM(A24)," ","*")&"*", CAM!$A:$A, CAM!$K:$K, "", 2), "") -> 1189 | C24: =IFERROR( _xlfn.XLOOKUP("*"&SUBSTITUTE(TRIM(A24)," ","*")&"*", CAM!$A:$A, CAM!$Z:$Z, "", 2), "")/12 -> 173 | D24: 6.67", QHD+, AMOLED | E24: 177 g | F24: IP68, IP69K, MIL-STD-810H | G24: 144 Hz | H24: Snapdragon 7s Gen 3 (4 nm) | I24: 807k | J24: 8 GB (física) + hasta 8 GB (RAM Boost) | K24: 256 GB UFS 2.2 | L24: NO | M24: 50 Mpx (ƒ/ 1.8) + 13 Mpx UGA (ƒ/ 2.2) | N24: SI | O24: 4K | P24: 32 Mpx | Q24: 5200 mAh | R24: 68.0W | S24: SI | T24: 6 | U24: SI | V24: Pantalla | W24: 6 años
A25: OPPO A5 256GB LTE | B25: =IFERROR( _xlfn.XLOOKUP("*"&SUBSTITUTE(TRIM(A25)," ","*")&"*", CAM!$A:$A, CAM!$K:$K, "", 2), "") -> 459 | C25: =IFERROR( _xlfn.XLOOKUP("*"&SUBSTITUTE(TRIM(A25)," ","*")&"*", CAM!$A:$A, CAM!$Z:$Z, "", 2), "")/12 -> 72 | D25: 6.67", HD+, LCD IPS | E25: 193 g | F25: IP65, MIL-STD-810H | G25: 90 Hz | H25: Snapdragon 6s Gen1 (11 nm) | I25: 405K | J25: 4 GB (física) + hasta 4 GB (RAM Boost) | K25: 256 GB UFS 2.1 | L25: Hasta 1TB | M25: 50 Mpx (ƒ/ 1.8) + 2 Mpx (ƒ/ 2.4) | N25: SI | O25: 1080p@30fps | P25: 5 Mpx | Q25: 6000 mAh | R25: 45.0W | S25: NO | T25: 5 | U25: SI | V25: lateral | W25: 5 años
A26: OPPO A5 256GB 5G | B26: =IFERROR( _xlfn.XLOOKUP("*"&SUBSTITUTE(TRIM(A26)," ","*")&"*", CAM!$A:$A, CAM!$K:$K, "", 2), "") -> 1199 | C26: =IFERROR( _xlfn.XLOOKUP("*"&SUBSTITUTE(TRIM(A26)," ","*")&"*", CAM!$A:$A, CAM!$Z:$Z, "", 2), "")/12 -> 175 | D26: 6.67", HD+, LCD IPS | E26: 194 g | F26: IP65, MIL-STD-810H | G26: 120Hz | H26: Dimensity 6300 (6 nm) | I26: 405K | J26: 8 GB (física) + hasta 8 GB (RAM Boost) | K26: 256 GB UFS 2.2 | L26: Hasta 1TB | M26: 50 Mpx (ƒ/ 1.8) + 2 Mpx (ƒ/ 2.4) | N26: SI | O26: 4K | P26: 8 Mpx | Q26: 6000 mAh | R26: 45.0W | S26: NO | T26: 5.3 | U26: SI | V26: lateral | W26: 5 años
A27: OPPO A5 PRO 256GB | B27: =IFERROR( _xlfn.XLOOKUP("*"&SUBSTITUTE(TRIM(A27)," ","*")&"*", CAM!$A:$A, CAM!$K:$K, "", 2), "") -> 1199 | C27: =IFERROR( _xlfn.XLOOKUP("*"&SUBSTITUTE(TRIM(A27)," ","*")&"*", CAM!$A:$A, CAM!$Z:$Z, "", 2), "")/12 -> 175 | D27: 6.67", HD+, LCD IPS | E27: 194 g | F27: IP68, IP69K, MIL-STD-810H | G27: 120Hz | H27: Dimensity 6300 (6 nm) | I27: 405K | J27: 8 GB (física) + hasta 8 GB (RAM Boost) | K27: 256 GB UFS 2.2 | L27: Hasta 1TB | M27: 50 Mpx (ƒ/ 1.8) + 2 Mpx (ƒ/ 2.4) | N27: SI | O27: 4K | P27: 8 Mpx | Q27: 5800 mAh | R27: 45.0W | S27: NO | T27: 5.3 | U27: SI | V27: lateral | W27: 5 años
A28: OPPO A6X 256GB 5G | B28: =IFERROR( _xlfn.XLOOKUP("*"&SUBSTITUTE(TRIM(A28)," ","*")&"*", CAM!$A:$A, CAM!$K:$K, "", 2), "") -> 799 | C28: =IFERROR( _xlfn.XLOOKUP("*"&SUBSTITUTE(TRIM(A28)," ","*")&"*", CAM!$A:$A, CAM!$Z:$Z, "", 2), "")/12 -> 113 | D28: 6.75", HD+, PLS | E28: 212 g | F28: IP 64 | G28: 120Hz | H28: Dimensity 6300 (6 nm) | I28: 405K | J28: 4 GB (física) + hasta 4 GB (RAM Boost) | K28: 256 GB UFS 2.2 | L28: Hasta 1TB | M28: 50 Mpx (ƒ/ 1.8) + 2 Mpx (ƒ/ 2.4) | N28: NO | O28: 1080p@30fps | P28: 5 Mpx | Q28: 6100 mAh | R28: 45.0W | S28: NO | T28: 5.4 | U28: SI | V28: lateral | W28: 5 años
A29: OPPO A6 PRO 256GB | B29: =IFERROR( _xlfn.XLOOKUP("*"&SUBSTITUTE(TRIM(A29)," ","*")&"*", CAM!$A:$A, CAM!$K:$K, "", 2), "") -> 1299 | C29: =IFERROR( _xlfn.XLOOKUP("*"&SUBSTITUTE(TRIM(A29)," ","*")&"*", CAM!$A:$A, CAM!$Z:$Z, "", 2), "")/12 -> 207 | D29: 6.57", FHD+, AMOLED | E29: 185 g | F29: IP69, MIL-STD-810H | G29: 120Hz | H29: Dimensity 6300 (6 nm) | I29: 409K | J29: 8 GB (física) + hasta 8 GB (RAM Boost) | K29: 256 GB UFS 2.2 | L29: Hasta 1TB | M29: 50 Mpx (ƒ/ 1.8) + 2 Mpx (ƒ/ 2.4) | N29: SI | O29: 4K | P29: 16 Mpx | Q29: 6500 mAh | R29: 80.0W | S29: NO | T29: 5.4 | U29: SI | V29: lateral | W29: 5 años
A30: OPPO RENO 14F 256GB 5G | B30: =IFERROR( _xlfn.XLOOKUP("*"&SUBSTITUTE(TRIM(A30)," ","*")&"*", CAM!$A:$A, CAM!$K:$K, "", 2), "") -> 1749 | C30: =IFERROR( _xlfn.XLOOKUP("*"&SUBSTITUTE(TRIM(A30)," ","*")&"*", CAM!$A:$A, CAM!$Z:$Z, "", 2), "")/12 -> 262 | D30: 6.57", FHD+, AMOLED | E30: 180 g | F30: IP68, IP69K | G30: 120Hz | H30: Snapdragon 6 Gen1 (4 nm) | I30: 575K | J30: 8 GB (física) + hasta 8 GB (RAM Boost) | K30: 256 GB UFS 3.1 | M30: 50 Mpx (ƒ/ 1.8) + 2 Mpx (ƒ/ 2.4) + 8 Mpx (ƒ/ 2.2) | N30: SI | O30: 4K | P30: 32 Mpx | Q30: 6000 mAh | R30: 45.0W | S30: NO | T30: 5.1 | U30: SI | V30: Pantalla | W30: 6 años
A31: SAMSUNG GXY A06 128GB | B31: =IFERROR( _xlfn.XLOOKUP("*"&SUBSTITUTE(TRIM(A31)," ","*")&"*", CAM!$A:$A, CAM!$K:$K, "", 2), "") -> 349 | C31: =IFERROR( _xlfn.XLOOKUP("*"&SUBSTITUTE(TRIM(A31)," ","*")&"*", CAM!$A:$A, CAM!$Z:$Z, "", 2), "")/12 -> 54 | D31: 6.7", HD+, PLS | E31: 189 g | F31: - | G31: 60 Hz | H31: Helio G85 (12 nm) | I31: 225K | J31: 4 GB (física) + hasta 4 GB (RAM Plus) | K31: 128 GB eMMC 5.1 | L31: Hasta 1TB | M31: 50 Mpx (ƒ/ 1.8) + 2 Mpx (ƒ/ 2.4) | N31: NO | O31: 1080p@60fps | P31: 8 Mpx | Q31: 5000 mAh | R31: 25.0W | S31: NO | T31: 5.3 | U31: NO | V31: lateral | W31: 46966
A32: SAMSUNG GXY A07 128GB | B32: =IFERROR( _xlfn.XLOOKUP("*"&SUBSTITUTE(TRIM(A32)," ","*")&"*", CAM!$A:$A, CAM!$K:$K, "", 2), "") -> 469 | C32: =IFERROR( _xlfn.XLOOKUP("*"&SUBSTITUTE(TRIM(A32)," ","*")&"*", CAM!$A:$A, CAM!$Z:$Z, "", 2), "")/12 -> 66 | D32: 6.7", HD+, PLS | E32: 184 g | F32: IP54 | G32: 90 Hz | H32: Helio G99 (6 nm) | I32: 416K | J32: 4 GB (física) + hasta 4 GB (RAM Plus) | K32: 128 GB eMMC 5.1 | L32: Hasta 2Tb | M32: 50 Mpx (ƒ/ 1.8) + 2 Mpx (ƒ/ 2.4) | N32: NO | O32: 1080p@30fps | P32: 8 Mpx | Q32: 5000 mAh | R32: 25.0W | S32: NO | T32: 5.3 | U32: NO | V32: lateral | W32: 48061
A33: SAMSUNG GXY A17 128GB | B33: =IFERROR( _xlfn.XLOOKUP("*"&SUBSTITUTE(TRIM(A33)," ","*")&"*", CAM!$A:$A, CAM!$K:$K, "", 2), "") -> 639 | C33: =IFERROR( _xlfn.XLOOKUP("*"&SUBSTITUTE(TRIM(A33)," ","*")&"*", CAM!$A:$A, CAM!$Z:$Z, "", 2), "")/12 -> 100 | D33: 6.7", FHD+, Super AMOLED | E33: 190 g | F33: IP54 | G33: 90 Hz | H33: Exynos 1330 (5 nm) | I33: 419K | J33: 8 GB (física) + hasta 8 GB (RAM Plus) | K33: 128 GB | L33: Hasta 2Tb | M33: 50 Mpx (ƒ/ 1.8) + 5 Mpx UGA (ƒ/ 2.2) + 2 Mpx MACRO (ƒ/ 2.4) | N33: SI | O33: 1080p@30fps | P33: 13 Mpx | Q33: 5000 mAh | R33: 25.0W | S33: NO | T33: 5.3 | U33: NO | V33: lateral | W33: 48092
A34: SAMSUNG GXY A16 128GB LTE | B34: =IFERROR( _xlfn.XLOOKUP("*"&SUBSTITUTE(TRIM(A34)," ","*")&"*", CAM!$A:$A, CAM!$K:$K, "", 2), "") -> 549 | C34: =IFERROR( _xlfn.XLOOKUP("*"&SUBSTITUTE(TRIM(A34)," ","*")&"*", CAM!$A:$A, CAM!$Z:$Z, "", 2), "")/12 -> 78 | D34: 6.7", FHD+, Super AMOLED | E34: 200 g | F34: IP54 | G34: 90 Hz | H34: Helio G99 (6 nm) | I34: 388K | J34: 4 GB (física) + hasta 4 GB (RAM Plus) | K34: 128 GB | L34: Hasta 1.5Tb | M34: 50 Mpx (ƒ/ 1.8) + 5 Mpx UGA (ƒ/ 2.2) + 2 Mpx MACRO (ƒ/ 2.4) | N34: NO | O34: 1080p@30fps | P34: 13 Mpx | Q34: 5000 mAh | R34: 25.0W | S34: NO | T34: 5.3 | U34: SI | V34: lateral | W34: 47788
A35: SAMSUNG GXY A26 128GB 5G | B35: =IFERROR( _xlfn.XLOOKUP("*"&SUBSTITUTE(TRIM(A35)," ","*")&"*", CAM!$A:$A, CAM!$K:$K, "", 2), "") -> 829 | C35: =IFERROR( _xlfn.XLOOKUP("*"&SUBSTITUTE(TRIM(A35)," ","*")&"*", CAM!$A:$A, CAM!$Z:$Z, "", 2), "")/12 -> 117 | D35: 6.7", FHD+, Super AMOLED | E35: 200 g | F35: IP67 | G35: 120 Hz | H35: Exynos 1380 (5 nm) | I35: 574K | J35: 6 GB (física) + hasta 6 GB (RAM Plus) | K35: 128 GB | L35: Hasta 2Tb | M35: 50 Mpx (ƒ/ 1.8) + 5 Mpx UGA (ƒ/ 2.2) + 2 Mpx (ƒ/ 2.4) | N35: SI | O35: 4K | P35: 13 Mpx | Q35: 5000 mAh | R35: 25.0W | S35: NO | T35: 5.3 | U35: SI | V35: lateral | W35: 47908
A36: SAMSUNG GXY A36 128GB 5G | B36: =IFERROR( _xlfn.XLOOKUP("*"&SUBSTITUTE(TRIM(A36)," ","*")&"*", CAM!$A:$A, CAM!$K:$K, "", 2), "") -> 949 | C36: =IFERROR( _xlfn.XLOOKUP("*"&SUBSTITUTE(TRIM(A36)," ","*")&"*", CAM!$A:$A, CAM!$Z:$Z, "", 2), "")/12 -> 134 | D36: 6.7", FHD+, Super AMOLED | E36: 195 g | F36: IP67 | G36: 120 Hz | H36: Snapdragon 6 Gen 3 (4 nm) | I36: 550K | J36: 6 GB (física) + hasta 6 GB (RAM Plus) | K36: 128 GB UFS 2.2 | L36: NO | M36: 50 Mpx (ƒ/ 1.8) + 8 Mpx UGA (ƒ/ 2.2) + 8 Mpx MACRO (ƒ/ 2.4) | N36: SI | O36: 4K | P36: 5 Mpx | Q36: 5000 mAh | R36: 45.0W | S36: NO | T36: 5.3 | U36: SI | V36: Pantalla | W36: 47908
A37: SAMSUNG GXY A37 256GB 5G | B37: =IFERROR( _xlfn.XLOOKUP("*"&SUBSTITUTE(TRIM(A37)," ","*")&"*", CAM!$A:$A, CAM!$K:$K, "", 2), "") -> 1739 | C37: =IFERROR( _xlfn.XLOOKUP("*"&SUBSTITUTE(TRIM(A37)," ","*")&"*", CAM!$A:$A, CAM!$Z:$Z, "", 2), "")/12 -> 246 | D37: 6.7", FHD+, Super AMOLED | E37: 196 g | F37: IP68 | G37: 120 Hz | H37: Exynos 1480 (4 nm) | I37: 731K | J37: 8 GB (física) + hasta 8 GB (RAM Plus) | K37: 256 GB UFS 3.1 | L37: - | M37: 50 Mpx (ƒ/ 1.8) + 8 Mpx UGA (ƒ/ 2.2) + 5 Mpx MACRO (ƒ/ 2.4) | N37: SI | O37: 4K | P37: 12 Mpx | Q37: 5000 mAh | R37: 45.0W | S37: NO | T37: 5.4 | U37: SI | V37: Pantalla | W37: 48274
A38: SAMSUNG GXY A56 256G 5G | B38: =IFERROR( _xlfn.XLOOKUP("*"&SUBSTITUTE(TRIM(A38)," ","*")&"*", CAM!$A:$A, CAM!$K:$K, "", 2), "") -> 1499 | C38: =IFERROR( _xlfn.XLOOKUP("*"&SUBSTITUTE(TRIM(A38)," ","*")&"*", CAM!$A:$A, CAM!$Z:$Z, "", 2), "")/12 -> 212 | D38: 6.7", FHD+, Super AMOLED | E38: 197 g | F38: IP67 | G38: 120 Hz | H38: Exynos 1580 (4 nm) | I38: 841K | J38: 8 GB (física) + hasta 8 GB (RAM Plus) | K38: 256 GB UFS 3.1 | L38: NO | M38: 50 Mpx (ƒ/ 1.8) + 13 Mpx UGA (ƒ/ 2.2) + 5 Mpx MACRO (ƒ/ 2.4) | N38: SI | O38: 4K | P38: 12 Mpx | Q38: 5000 mAh | R38: 45.0W | S38: NO | T38: 5.3 | U38: SI | V38: Pantalla | W38: 48274
A39: SAMSUNG GXY A57 256G 5G | B39: =IFERROR( _xlfn.XLOOKUP("*"&SUBSTITUTE(TRIM(A39)," ","*")&"*", CAM!$A:$A, CAM!$K:$K, "", 2), "") -> 1939 | C39: =IFERROR( _xlfn.XLOOKUP("*"&SUBSTITUTE(TRIM(A39)," ","*")&"*", CAM!$A:$A, CAM!$Z:$Z, "", 2), "")/12 -> 275 | D39: 6.7", FHD+, Super AMOLED+ | F39: IP68 | G39: 120 Hz | H39: Exynos 1680 (4 nm) | I39: 1120K | J39: 8 GB (física) + hasta 8 GB (RAM Plus) | K39: 256 GB UFS 3.1 | L39: - | M39: 50 Mpx (ƒ/ 1.8) + 8 Mpx UGA (ƒ/ 2.2) + 5 Mpx MACRO (ƒ/ 2.4) | N39: SI | O39: 4K | P39: 12 Mpx | Q39: 5000 mAh | R39: 45.0W | S39: NO | T39: 6 | U39: SI | V39: Pantalla | W39: 48274
A40: SAMSUNG GXY S26 256GB | B40: =IFERROR( _xlfn.XLOOKUP("*"&SUBSTITUTE(TRIM(A40)," ","*")&"*", CAM!$A:$A, CAM!$K:$K, "", 2), "") -> 3799 | C40: =IFERROR( _xlfn.XLOOKUP("*"&SUBSTITUTE(TRIM(A40)," ","*")&"*", CAM!$A:$A, CAM!$Z:$Z, "", 2), "")/12 -> 538 | D40: 6.3", FHD+, Dynamic AMOLED 2X | E40: 167 g | F40: IP68 | G40: 120 Hz | H40: Exynos 2600 (2 nm) | I40: 2825K | J40: 12 GB (física) + hasta 8 GB (RAM Plus) | K40: 256 GB UFS 4.1 | L40: NO | M40: 50 Mpx (ƒ/ 1.8) + 12 Mpx UGA (ƒ/ 2.2) + 12 Mpx Teleobjetivo (ƒ/ 2.4) | N40: SI | O40: 8K | P40: 12 Mpx | Q40: 4300 mAh | R40: 25.0W | S40: SI, 15W | T40: 5.4 | U40: SI | V40: Pantalla | W40: 48611
...

Sheet CAM
A1: Modelo | B1: 29.9 | C1: 35.9 | D1: 39.9 | E1: 45.9 | F1: 49.9 | G1: 55.9 | H1: 59.9 | I1: 65.9 | J1: 69.9 | K1: 74.9 | L1: 79.9 | M1: 85.9 | N1: 99.9 | O1: 114.9 | P1: Planes MT | Q1: 29.9 | R1: 35.9 | S1: 39.9 | T1: 45.9 | U1: 49.9 | V1: 55.9 | W1: 59.9 | X1: 65.9 | Y1: 69.9 | Z1: 74.9 | AA1: 79.9 | AB1: 85.9 | AC1: 99.9 | AD1: 114.9 | AE1: MT
A2: SAMSUNG GXY A12 SM-A127MZ LTE | B2: 299 | C2: 299 | D2: 299 | E2: 299 | F2: 299 | G2: 299 | H2: 299 | I2: 299 | J2: 299 | K2: 299 | L2: 299 | M2: 299 | N2: 299 | O2: 299 | P2: 299 | Q2: 0 | R2: 0 | S2: 0 | T2: 0 | U2: 0 | V2: 0 | W2: 0 | X2: 0 | Y2: 0 | Z2: 0 | AA2: 0 | AB2: 0 | AC2: 0 | AD2: 0 | AE2: 0
A3: SAMSUNG GXY A32 SM-A325MZ LTE | B3: 969 | C3: 969 | D3: 969 | E3: 949 | F3: 949 | G3: 949 | H3: 949 | I3: 939 | J3: 939 | K3: 939 | L3: 939 | M3: 909 | N3: 909 | O3: 909 | P3: 939 | Q3: 0 | R3: 0 | S3: 0 | T3: 0 | U3: 0 | V3: 0 | W3: 0 | X3: 0 | Y3: 0 | Z3: 0 | AA3: 0 | AB3: 0 | AC3: 0 | AD3: 0 | AE3: 0
A4: XIAOMI REDMI NOTE 10S LTE | B4: 1189 | C4: 1189 | D4: 1189 | E4: 1159 | F4: 1159 | G4: 1159 | H4: 1159 | I4: 1139 | J4: 1139 | K4: 1139 | L4: 1139 | M4: 1099 | N4: 1099 | O4: 1099 | P4: 1139 | Q4: 2376 | R4: 2376 | S4: 2376 | T4: 2244 | U4: 2244 | V4: 2244 | W4: 2244 | X4: 2112 | Y4: 2112 | Z4: 2112 | AA4: 2112 | AB4: 2112 | AC4: 2112 | AD4: 2112 | AE4: 2112
A5: ZTE BLADE A5 2020 LTE | B5: 399 | C5: 399 | D5: 399 | E5: 399 | F5: 399 | G5: 399 | H5: 399 | I5: 399 | J5: 399 | K5: 399 | L5: 399 | M5: 399 | N5: 399 | O5: 399 | P5: 399 | Q5: 0 | R5: 0 | S5: 0 | T5: 0 | U5: 0 | V5: 0 | W5: 0 | X5: 0 | Y5: 0 | Z5: 0 | AA5: 0 | AB5: 0 | AC5: 0 | AD5: 0 | AE5: 0
A6: ZTE BLADE A31 LTE | B6: 339 | C6: 339 | D6: 339 | E6: 339 | F6: 339 | G6: 329 | H6: 329 | I6: 319 | J6: 319 | K6: 319 | L6: 319 | M6: 319 | N6: 319 | O6: 319 | P6: 319 | Q6: 0 | R6: 0 | S6: 0 | T6: 0 | U6: 0 | V6: 0 | W6: 0 | X6: 0 | Y6: 0 | Z6: 0 | AA6: 0 | AB6: 0 | AC6: 0 | AD6: 0 | AE6: 0
A7: ZTE BLADE A51 LTE | B7: 299 | C7: 299 | D7: 299 | E7: 299 | F7: 299 | G7: 299 | H7: 299 | I7: 299 | J7: 299 | K7: 299 | L7: 299 | M7: 299 | N7: 299 | O7: 299 | P7: 299 | Q7: 924 | R7: 924 | S7: 924 | T7: 876 | U7: 876 | V7: 876 | W7: 876 | X7: 828 | Y7: 828 | Z7: 828 | AA7: 828 | AB7: 828 | AC7: 828 | AD7: 828 | AE7: 828
A8: ZTE BLADE A71 LTE | B8: 249 | C8: 249 | D8: 249 | E8: 249 | F8: 249 | G8: 249 | H8: 249 | I8: 249 | J8: 249 | K8: 249 | L8: 249 | M8: 249 | N8: 249 | O8: 249 | P8: 249 | Q8: 924 | R8: 924 | S8: 924 | T8: 876 | U8: 876 | V8: 876 | W8: 876 | X8: 828 | Y8: 828 | Z8: 828 | AA8: 828 | AB8: 828 | AC8: 828 | AD8: 828 | AE8: 828
A9: IPHONE 13 128GB | B9: 1989 | C9: 1989 | D9: 1989 | E9: 1989 | F9: 1989 | G9: 1989 | H9: 1989 | I9: 1989 | J9: 1989 | K9: 1989 | L9: 1989 | M9: 1899 | N9: 1899 | O9: 1899 | P9: 1899 | Q9: 0 | R9: 0 | S9: 0 | T9: 3384 | U9: 3384 | V9: 3384 | W9: 3384 | X9: 3036 | Y9: 3036 | Z9: 3036 | AA9: 3036 | AB9: 4092 | AC9: 4092 | AD9: 4092 | AE9: 3384
A10: SAMSUNG GXY A03 CORE SM-A032MZ LTE | B10: 449 | C10: 449 | D10: 449 | E10: 439 | F10: 439 | G10: 439 | H10: 439 | I10: 429 | J10: 429 | K10: 429 | L10: 429 | M10: 419 | N10: 419 | O10: 419 | P10: 429 | Q10: 888 | R10: 888 | S10: 888 | T10: 840 | U10: 840 | V10: 840 | W10: 840 | X10: 792 | Y10: 792 | Z10: 792 | AA10: 792 | AB10: 792 | AC10: 792 | AD10: 792 | AE10: 792
A11: OPPO A16 64GB LTE | B11: 709 | C11: 709 | D11: 709 | E11: 689 | F11: 689 | G11: 689 | H11: 689 | I11: 679 | J11: 679 | K11: 679 | L11: 679 | M11: 659 | N11: 659 | O11: 659 | P11: 679 | Q11: 1416 | R11: 1416 | S11: 1416 | T11: 1332 | U11: 1332 | V11: 1332 | W11: 1332 | X11: 1260 | Y11: 1260 | Z11: 1260 | AA11: 1260 | AB11: 1260 | AC11: 1260 | AD11: 1260 | AE11: 1260
A12: SAMSUNG GXY A53 SM-A536M 5G | B12: 799 | C12: 799 | D12: 799 | E12: 799 | F12: 799 | G12: 799 | H12: 799 | I12: 799 | J12: 799 | K12: 799 | L12: 799 | M12: 799 | N12: 799 | O12: 799 | P12: 799 | Q12: 2700 | R12: 2700 | S12: 2700 | T12: 2544 | U12: 2544 | V12: 2544 | W12: 2544 | X12: 2400 | Y12: 2400 | Z12: 2400 | AA12: 2400 | AB12: 2400 | AC12: 2400 | AD12: 2400 | AE12: 2400
A13: SAMSUNG GXY A23 SM-A235M 128GB LTE | B13: 499 | C13: 499 | D13: 499 | E13: 499 | F13: 499 | G13: 499 | H13: 499 | I13: 499 | J13: 499 | K13: 499 | L13: 499 | M13: 499 | N13: 499 | O13: 499 | P13: 499 | Q13: 1452 | R13: 1452 | S13: 1452 | T13: 1368 | U13: 1368 | V13: 1368 | W13: 1368 | X13: 1296 | Y13: 1296 | Z13: 1296 | AA13: 1296 | AB13: 1296 | AC13: 1296 | AD13: 1296 | AE13: 1296
... A190: XIAOMI REDMI A7 PRO 128GB LTE | B190: 559 | C190: 559 | D190: 559 | E190: 499 | F190: 499 | G190: 499 | H190: 499 | I190: 499 | J190: 499 | K190: 499 | L190: 499 | M190: 499 | N190: 499 | O190: 499 | P190: 499 | Q190: 1032 | R190: 1032 | S190: 1032 | T190: 936 | U190: 936 | V190: 936 | W190: 936 | X190: 852 | Y190: 852 | Z190: 852 | AA190: 852 | AB190: 852 | AC190: 852 | AD190: 852 | AE190: 852

Sheet Imagen
A1: CATALOGO DE EQUIPOS
A2: HONOR 400 | B2: IMAGEN | C2: https://embed.studio.binkies3d.com/live3d/69e129b874c82e003663da95
A3: HONOR 400 LITE | B3: IMAGEN | C3: https://embed.studio.binkies3d.com/live3d/69e129f8a8d031003791f1a7
A4: HONOR MAGIC 7 LITE 512GB | B4: IMAGEN | C4: https://embed.studio.binkies3d.com/live3d/69e12a7bc7300c00376148d6
A5: HONOR MAGIC 8 LITE 512GB 5G | B5: IMAGEN | C5: https://embed.studio.binkies3d.com/live3d/69e12ab0492f94003516cc8a
A6: HONOR X5B 128GB | B6: IMAGEN | C6: https://embed.studio.binkies3d.com/live3d/69e12ae6c7300c0037614948
A7: HONOR X5C 128GB | B7: IMAGEN | C7: https://embed.studio.binkies3d.com/live3d/69e12b6dc7300c00376149a0
A8: HONOR X6C 256GB | B8: IMAGEN | C8: https://embed.studio.binkies3d.com/live3d/69e12b92c7300c00376149f6
A9: HONOR X7C 256GB | B9: IMAGEN | C9: https://embed.studio.binkies3d.com/live3d/69e12bf5492f94003516cd5f
A10: HONOR X7D 256GB LTE | B10: IMAGEN | C10: https://embed.studio.binkies3d.com/live3d/69e12c1ca8d031003791f20b
A11: HONOR X8C 256GB | B11: IMAGEN | C11: https://embed.studio.binkies3d.com/live3d/69e12c4bc7300c0037614a81
A12: IPHONE 13 128GB | B12: IMAGEN | C12: https://embed.studio.binkies3d.com/live3d/69e12c8cc7300c0037614adf
A13: IPHONE 15 128GB | B13: IMAGEN | C13: https://embed.studio.binkies3d.com/live3d/69e12ccac7300c0037614b7e
... A63: SAMSUNG GXY S26 ULTRA 256GB | B63: IMAGEN | C63: https://embed.studio.binkies3d.com/live3d/69eaa43950dfff0035ea3e84

Sheet Imagen (2)
A1: CATALOGO DE EQUIPOS
A2: HONOR MAGIC 7 LITE 512GB | B2: IMAGEN PARTE DELANTERA | C2: https://i.ebayimg.com/images/g/vOkAAOSwgkBnhgYQ/s-l1600.webp | D2: IMAGEN PARTE TRASERA | E2: https://i.ebayimg.com/images/g/87cAAOSwD1NnhgYT/s-l1600.webp
A3: HONOR X5B 128GB | B3: IMAGEN PARTE DELANTERA | C3: https://covercompany.com.uy/cdn/shop/files/2-5934_14201_4.jpg?v=1732820170 | D3: IMAGEN PARTE TRASERA | E3: https://covercompany.com.uy/cdn/shop/files/2-5934_14201_3.jpg?v=1732819982
A4: HONOR X6C 256GB | B4: IMAGEN PARTE DELANTERA | C4: https://www.peru-smart.com/wp-content/uploads/2025/07/CELU1107AZUL-256GB_1.jpg | D4: IMAGEN PARTE TRASERA | E4: https://www.peru-smart.com/wp-content/uploads/2025/07/CELU1107AZUL-256GB_0.jpg
A5: HONOR X7C 256GB | B5: IMAGEN PARTE DELANTERA | C5: https://webstoreshops.com/cdn/shop/files/HONOR_X7C_White-3.jpg?v=1737559775&width=800 | D5: IMAGEN PARTE TRASERA | E5: https://webstoreshops.com/cdn/shop/files/HONOR_X7C_White-2.jpg?v=1737559961&width=800
A6: HONOR X8C 256GB | B6: IMAGEN PARTE DELANTERA | C6: https://rimage.ripley.com.pe/home.ripley/Attachment/MKP/3539/PMP20000745981/full_image-1.jpeg | D6: IMAGEN PARTE TRASERA | E6: https://soytechno.com/wp-content/uploads/2025/05/HONOR-X8C-ABR-LX3-CLOUD-PURPLE-3.jpg
A7: IPHONE 13 128GB | B7: IMAGEN PARTE DELANTERA | C7: https://inverfin.com.py/cdn/shop/files/99991627492109_TEL.IPH.13.128.BLA_1.jpg?v=1725987794&width=823 | D7: IMAGEN PARTE TRASERA | E7: https://me-tiendamexpress.s3.us-east-1.amazonaws.com/images/thumbs/0059161_celular-apple-iphone-13-128gb-blanco_600.jpeg
A8: MOTOROLA G05 128GB | B8: IMAGEN PARTE DELANTERA | C8: https://m.media-amazon.com/images/I/71OVsSh822L._AC_SX569_.jpg | D8: IMAGEN PARTE TRASERA | E8: https://m.media-amazon.com/images/I/81RrrX8vpIL._AC_SX569_.jpg
A9: MOTOROLA G15 256GB | B9: IMAGEN PARTE DELANTERA | C9: https://m.media-amazon.com/images/I/51daXYKSyOL._AC_SX679_.jpg | D9: IMAGEN PARTE TRASERA | E9: https://m.media-amazon.com/images/I/619G60+TY-L._AC_SX679_.jpg
A10: MOTOROLA G56 256GB | B10: IMAGEN PARTE DELANTERA | C10: https://bsimg.nl/images/motorola-moto-g56-5g-8gb-256gb-groen_1.png/n-s3tDVQ3aeoNxKSrJEA0et3_G8%3D/fit-in/771x1200/filters%3Aformat%28webp%29%3Aupscale%28%29 | D10: IMAGEN PARTE TRASERA | E10: https://bsimg.nl/images/motorola-moto-g56-5g-8gb-256gb-groen_2.png/kGRkER2wCFObuCEv4y-YAoPdVnc%3D/fit-in/771x1200/filters%3Aformat%28webp%29%3Aupscale%28%29
A11: MOTOROLA EDGE 60 FUSION 256GB 5G | B11: IMAGEN PARTE DELANTERA | C11: https://cdn-files.kimovil.com/phone_front/0011/67/thumb_1066808_phone_front_big.jpg | D11: IMAGEN PARTE TRASERA | E11: https://cdn-files.kimovil.com/default/0011/67/thumb_1066804_default_big.jpg
A12: OPPO A5 256GB 5G | B12: IMAGEN PARTE DELANTERA | C12: https://www.maxmovil.com/media/catalog/product/cache/2c055c968235f5bf43b443aee4bb62c6/o/p/oppo_a5_5g_verde_2_.png | D12: IMAGEN PARTE TRASERA | E12: https://www.ispotaba.com/wp-content/uploads/2025/07/Oppo-A5-Mist-White-Back.jpg
A13: OPPO A5 PRO 256GB | B13: IMAGEN PARTE DELANTERA | C13: https://www.maxmovil.com/media/catalog/product/cache/2c055c968235f5bf43b443aee4bb62c6/o/p/oppo_a5_pro_5g_verde_1_.png | D13: IMAGEN PARTE TRASERA | E13: https://www.maxmovil.com/media/catalog/product/cache/2c055c968235f5bf43b443aee4bb62c6/o/p/oppo_a5_pro_5g_verde_4_.png
... A58: ZTE NUBIA V80 MAX 256GB LTE | B58: IMAGEN PARTE DELANTERA | C58: https://claroperupoc.vtexassets.com/arquivos/ids/2956850/ZTE-NUBIA-V80-MAX-256GB-NEGRO-04.jpg?v=639105733666730000 | D58: IMAGEN PARTE TRASERA | E58: https://claroperupoc.vtexassets.com/arquivos/ids/2956848/ZTE-NUBIA-V80-MAX-256GB-NEGRO-02.jpg?v=639105733666430000

Sheet Precio
A1: En precio, quiero que vaya dos segmentos: Contado y cuota x 12 meses. Tambien cuando el mouse pase por la imagen diga algo como "haz click para voltear la imagen".
A2: EQUIPO | B2: PRECIO AL CONTADO | C2: FINANCIADO | D2: CUOTA X 12 MESES
A3: HONOR MAGIC 7 LITE 512GB | B3: 1399 | C3: 2448 | D3: =C3/12 -> 204
A4: HONOR X5B 128GB | B4: 399 | C4: 732 | D4: =C4/12 -> 61
A5: HONOR X6C 256GB | B5: 579 | C5: 1080 | D5: =C5/12 -> 90
A6: HONOR X7C 256GB | B6: 749 | C6: 1404 | D6: =C6/12 -> 117
A7: HONOR X8C 256GB | B7: 899 | C7: 1644 | D7: =C7/12 -> 137
A8: IPHONE 13 128GB | B8: 2009 | C8: 3516 | D8: =C8/12 -> 293
A9: MOTOROLA G05 128GB | B9: 349 | C9: 648 | D9: =C9/12 -> 54
A10: MOTOROLA G15 256GB | B10: 469 | C10: 876 | D10: =C10/12 -> 73
A11: MOTOROLA G56 256GB | B11: 849 | C11: 1584 | D11: =C11/12 -> 132
A12: OPPO A5 5G 256GB | B12: 999 | C12: 1824 | D12: =C12/12 -> 152
A13: OPPO A5 PRO 256GB | B13: 1299 | C13: 2268 | D13: =C13/12 -> 189
A14: OPPO A5 4G 256GB | B14: 699 | C14: 1284 | D14: =C14/12 -> 107
... A27: ZTE BLADE V70 MAX 256GB | B27: 449 | C27: 840 | D27: =C27/12 -> 70

Sheet Hoja3
A1: 📱 Pantalla | B1: 6.78" AMOLED | C1: 6.56" IPS LCD | D1: 6.56" IPS LCD
A2: 💧 Resistencia al Agua | B2: IP64 | C2: No | D2: No
A3: 🔄 Tasa de Refresco | B3: 120Hz | C3: 90Hz | D3: 90Hz
A4: ⚡ Procesador | B4: Snapdragon 6 Gen 1 | C4: Unisoc Tiger T606 | D4: Unisoc Tiger T606
A5: 🧠 RAM | B5: 8GB | C5: 4GB | D5: 4GB
A6: 💾 Almacenamiento | B6: 512GB | C6: 128GB | D6: 256GB
A7: 📷 Cámaras Traseras | B7: 3 cámaras traseras | C7: 1 cámara trasera | D7: 2 cámaras traseras
A8: 📸 Cámara Principal | B8: 108MP Principal | C8: 50MP Principal | D8: 50MP Principal
A9: 📐 Cámara Ultra Gran Angular | B9: 5MP Ultra Gran Angular | C9: No | D9: 2MP Profundidad
A10: 🔭 Cámara Teleobjetivo | B10: 2MP Macro | C10: No | D10: No
A11: 🔍 Cámara Macro | B11: Sí | C11: No | D11: No
A12: 📹 Estabilización Óptica | B12: No | C12: No | D12: No
... A20: ⚖️ Peso | B20: 189g | C20: 192g | D20: 194g

Sheet link
A1: LAS ESPECIFICACIONES COMO EL PROCESADOR, BATERIA, RESISTENCIA, PANTALLA, ETC. REVISA DESDE EL FONDO. IPHONE 13 https://www.kimovil.com/es/donde-comprar-apple-iphone-13 HONOR X5B https://www.kimovil.com/es/donde-comprar-honor-x5b HONOR X6C https://www.kimovil.com/es/donde-comprar-honor-x6b HONOR X7C https://www.honor.com/mx/phones/honor-7c/spec/ HONOR X8C https://www.kimovil.com/es/donde-comprar-honor-x8c MOTO G05 https://www.kimovil.com/es/donde-comprar-motorola-moto-g05 MOTO G15 https://www.kimovil.com/es/donde-comprar-motorola-moto-g15 MOTO G56 https://www.kimovil.com/es/donde-comprar-motorola-moto-g56-5g OPPO A5 PRO https://www.kimovil.com/es/donde-comprar-oppo-a5-pro-5g RENO 14F https://www.kimovil.com/es/donde-comprar-oppo-reno14-f SAMSUNG A06 https://www.kimovil.com/es/donde-comprar-samsung-galaxy-a06 SAMSUNG A16 https://www.kimovil.com/es/donde-comprar-samsung-galaxy-a16-4g SAMSUNG A26 https://www.kimovil.com/es/donde-comprar-samsung-galaxy-a26-5g SAMSUNG A36 https://www.kimovil.com/es/donde-comprar-samsung-galaxy-a36 SAMSUNG A56 https://www.kimovil.com/es/donde-comprar-samsung-galaxy-a56 XIAOMI REDMI NOTE 14 https://www.kimovil.com/es/donde-comprar-xiaomi-redmi-note-14 XIAOMI REDMI NOTE 14 PRO 4G https://www.kimovil.com/es/donde-comprar-xiaomi-redmi-note-14-pro-4g ZTE BLADE A35 https://www.kimovil.com/es/donde-comprar-zte-blade-a35 ZTE BLADE A55 https://www.kimovil.com/es/donde-comprar-zte-blade-a55 ZTE BLADE A56 PRO https://miportal.entel.pe/personas/producto/equipos/zte-blade-a56-pro/prod940041 ZTE BLADE V70 https://www.ztedevices.com/en/products/smartphones/blade/zte-blade-v70.html ZTE BLADE V70 VITA https://www.kimovil.com/es/donde-comprar-zte-blade-v70-vita
